<?xml version="1.0" encoding="utf-8"?>

<robot name="robot" xmlns:xacro="http://www.ros.org/wiki/xacro">
    <xacro:property name="length_wheel" value="0.116" />
    <xacro:property name="radius_wheel" value="0.165" />
    <xacro:property name="PI" value="3.1415926"/>
	<xacro:property name="wheel_kp" value="1000000"/>
	<xacro:property name="wheel_kd" value="1"/>
    <xacro:macro name="default_inertial" params="mass">
		<inertial>
			<mass value="1"/>
			<inertia ixx="0.1" ixy="0.0" ixz="0.0" iyy="0.1" iyz="0.0" izz="0.1" />
		</inertial>
	</xacro:macro>
  
  	<link name="base_link">
    	<visual>
    		<geometry>
      			<box size="1.00 0.4 0.2"/>
    		</geometry>
			<origin rpy="0 0 0" xyz="0 0 0"/>
			<material name="white">
				<color rgba="1 1 1 1"/>
			</material>
    	</visual>
		<collision>
			<geometry>
       			<box size="1.0 0.4 0.2"/>
			</geometry>
		</collision>
    	<xacro:default_inertial mass="0.1"/>    
 	</link>

 	<link name="wheel_1">
		<visual>
			<geometry>
				<cylinder length="${length_wheel}" radius="${radius_wheel}"/>
			</geometry>
			<origin rpy="0 0 0" xyz="0 0 0"/>
			<material name="black">
				<color rgba="0 0 0 1"/>
			</material>
		</visual>
		<collision>
			<origin rpy="0 0 0" xyz="0 0 0"/>
			<geometry>
        		<cylinder length="${length_wheel}" radius="${radius_wheel}"/>
			</geometry>
		</collision>
      	<mu1>0.5</mu1>
		<mu2>0.5</mu2>
		<xacro:default_inertial mass="0.01"/>  
 	</link>

 	<link name="wheel_2">
		<visual>
			<geometry>
				<cylinder length="${length_wheel}" radius="${radius_wheel}"/>
			</geometry>
			<origin rpy="0 0 0" xyz="0 0 0"/>
			<material name="black"/>
		</visual>
		<collision>
			<origin rpy="0 0 0" xyz="0 0 0"/>
			<geometry>
        		<cylinder length="${length_wheel}" radius="${radius_wheel}"/>
			</geometry>
		</collision>
    	<mu1>0.5</mu1>
    	<mu2>0.5</mu2>
		<xacro:default_inertial mass="0.01"/>  
 	</link>
    
 	<link name="wheel_3">
		<visual>
			<geometry>
				<cylinder length="${length_wheel}" radius="${radius_wheel}"/>
			</geometry>
					<origin rpy="0 0 0" xyz="0 0 0"/>
			<material name="black"/>
		</visual>
		<collision>
			<origin rpy="0 0 0" xyz="0 0 0"/>
			<geometry>
        		<cylinder length="${length_wheel}" radius="${radius_wheel}"/>
			</geometry>
		</collision>
		<mu1>0.5</mu1>
		<mu2>0.5</mu2>
		<xacro:default_inertial mass="0.01"/>    
 	</link>

 	<link name="wheel_4">
		<visual>
			<geometry>
				<cylinder length="${length_wheel}" radius="${radius_wheel}"/>
			</geometry>
			<origin rpy="0 0 0" xyz="0 0 0"/>
			<material name="black"/>
		</visual>
		<collision>
			<origin rpy="0 0 0" xyz="0 0 0"/>
			<geometry>
        		<cylinder length="${length_wheel}" radius="${radius_wheel}"/>
			</geometry>
		</collision>
		<mu1>0.5</mu1>
		<mu2>0.5</mu2>
		<xacro:default_inertial mass="0.01"/>    
 	</link>

  	<link name="imu">
		<collision>
			<origin xyz="0 0 0" rpy="0 0 0"/>
			<geometry>
				<box size="0.1 0.1 0.1"/>
			</geometry>
		</collision>

    	<visual>
      		<origin xyz="0 0 0" rpy="0 0 0"/>
			<geometry>
				<box size="0.1 0.1 0.1"/>
			</geometry>
      		<material name="blue">
        		<color rgba="0 1 0 1"/>
      		</material>
    	</visual>

		<inertial>
			<mass value="1e-4" />
			<origin xyz="0 0 0" rpy="0 0 0"/>
			<inertia ixx="1e-6" ixy="0" ixz="0" iyy="1e-6" iyz="0" izz="1e-6" />
		</inertial>
  	</link>

	<link name="rslidar">
		<collision>
			<origin xyz="0 0 0" rpy="0 0 0"/>
			<geometry>
				<cylinder length="0.1" radius="0.06"/>
			</geometry>
		</collision>

		<visual>
			<origin xyz="0 0 0" rpy="0 0 0"/>
			<geometry>
				<cylinder length="0.1" radius="0.06"/>
			</geometry>
		</visual>

		<inertial>
			<mass value="1e-4" />
			<origin xyz="0 0 0" rpy="0 0 0"/>
			<inertia ixx="1e-6" ixy="0" ixz="0" iyy="1e-6" iyz="0" izz="1e-6" />
		</inertial>
	</link>


	<joint name="base_to_wheel1" type="continuous">
		<parent link="base_link"/>
		<child link="wheel_1"/>
		<origin rpy="${-PI/2} 0 0" xyz="0.25 0.30 0"/>
		<axis xyz="0 0 1" />
	</joint>

	<joint name="base_to_wheel2" type="continuous">
		<axis xyz="0 0 1" />
		<parent link="base_link"/>
		<child link="wheel_2"/>
		<origin rpy="${-PI/2} 0 0" xyz="-0.25 0.30 0"/>
	</joint>

	<joint name="base_to_wheel3" type="continuous">
		<parent link="base_link"/>
		<axis xyz="0 0 1" />
		<child link="wheel_3"/>
		<origin rpy="${-PI/2} 0 0" xyz="0.25 -0.3 0"/>
	</joint>

	<joint name="base_to_wheel4" type="continuous">
		<parent link="base_link"/>
		<axis xyz="0 0 1" />
		<child link="wheel_4"/>
		<origin rpy="${-PI/2} 0 0" xyz="-0.25 -0.3 0"/>
	</joint>

	<joint name="imu_joint" type="fixed">
		<axis xyz="0 1 0" />
		<origin xyz="0.2 0 0.15" rpy="0 0 0"/>
		<parent link="base_link"/>
		<child link="imu"/>
	</joint>

	<joint name="rslidar_joint" type="fixed">
		<origin xyz="0.2 0.0 0.25" rpy="0 0 0"/>
		<parent link="base_link"/>
		<axis xyz="0 1 0" />
		<child link="rslidar"/>
	</joint>


	<gazebo reference="base_link">
		<material>Gazebo/DarkGrey</material>
	</gazebo>

	<gazebo reference="wheel_1">
		<material>Gazebo/Red</material>
	</gazebo>

	<gazebo reference="wheel_2">
		<material>Gazebo/Blue</material>
	</gazebo>

	<gazebo reference="wheel_3">
    	<material>Gazebo/Red</material>
 	</gazebo>

	<gazebo reference="wheel_4">
    	<material>Gazebo/Blue</material>
	</gazebo>

	<gazebo>
		<!-- <plugin name="motion_controller" filename="libgazebo_ros_skid_steer_drive.so">
			<commandTopic>cmd_vel</commandTopic>
			<odometryTopic>odom</odometryTopic>
			<odometryFrame>odom</odometryFrame>
			<robotNamespace>/</robotNamespace>
			<leftFrontJoint>base_to_wheel1</leftFrontJoint>
			<rightFrontJoint>base_to_wheel3</rightFrontJoint>
			<leftRearJoint>base_to_wheel2</leftRearJoint>
			<rightRearJoint>base_to_wheel4</rightRearJoint>
			<odometryRate>0.0</odometryRate>
			<torque>1</torque>
			<wheelDiameter>0.330</wheelDiameter>
			<wheelSeparation>0.582</wheelSeparation>
			<updateRate>100</updateRate>
			<robotBaseFrame>base_link</robotBaseFrame>
		</plugin> -->
		<plugin name="diff_controller" filename="libgazebo_ros_planar_move.so">
			<commandTopic>cmd_vel</commandTopic>
			<odometryTopic>odom</odometryTopic>
			<odometryFrame>odom</odometryFrame>
			<robotNamespace>/</robotNamespace>
			<leftFrontJoint>base_to_wheel1</leftFrontJoint>
			<rightFrontJoint>base_to_wheel3</rightFrontJoint>
			<leftRearJoint>base_to_wheel2</leftRearJoint>
			<rightRearJoint>base_to_wheel4</rightRearJoint>
			<odometryRate>0.0</odometryRate>
			<robotBaseFrame>base_link</robotBaseFrame>
		</plugin>
	</gazebo>

	<gazebo reference="imu">
		<material>Gazebo/White</material>
		<gravity>true</gravity>
		<sensor name="imu_sensor" type="imu">
			<always_on>true</always_on>
			<update_rate>100</update_rate>
			<visualize>true</visualize>
			<topic>imu</topic>
			<plugin filename="libgazebo_ros_imu_sensor.so" name="imu_plugin">
				<topicName>imu</topicName>
				<bodyName>imu</bodyName>
				<updateRateHZ>100.0</updateRateHZ>
				<gaussianNoise>0.0</gaussianNoise>
				<xyzOffset>0 0 0</xyzOffset>
				<rpyOffset>0 0 0</rpyOffset>
				<frameName>imu</frameName>
			</plugin>
			<pose>0 0 0 0 0 0</pose>
		</sensor>
	</gazebo>

	<gazebo reference="rslidar">
		<material>Gazebo/DarkGrey</material>
		<sensor type="ray" name="sl_a1">
			<pose>0 0 0 0 0 0</pose>
			<visualize>false</visualize>
			<update_rate>10</update_rate>
			<ray>
				<scan>
					<horizontal>
						<samples>2000</samples>
						<resolution>1</resolution>
						<min_angle>-${PI}</min_angle>
						<max_angle>${PI}</max_angle>
					</horizontal>
					<vertical>
						<samples>1</samples>
						<resolution>1</resolution>
						<min_angle>-${0*PI/180.0}</min_angle>
						<max_angle> ${0*PI/180.0}</max_angle>
					</vertical>
				</scan>
				<range>
					<min>0.2</min>
					<max>100.0</max>
					<resolution>0.001</resolution>
				</range>
				<noise>
					<type>gaussian</type>
					<mean>0.0</mean>
					<stddev>0.0</stddev>
				</noise>
			</ray>
			<plugin name="gazebo_ros_laser_controller" filename="libgazebo_ros_ray_sensor.so">
				<topicName>/scan</topicName>
				<frameName>rslidar</frameName>
				<organize_cloud>false</organize_cloud>
				<min_range>0.2</min_range>
				<max_range>100.0</max_range>
				<gaussianNoise>0.008</gaussianNoise>
			</plugin>
		</sensor>
	</gazebo>

</robot>
