<?xml version="1.0" ?>
<!-- =================================================================================== -->
<!-- |    This document was autogenerated by xacro from caterpillar_robot.xacro        | -->
<!-- |    EDITING THIS FILE BY HAND IS NOT RECOMMENDED                                 | -->
<!-- =================================================================================== -->
<robot name="mycar">
  <link name="base_footprint"/>
  <link name="base_link">
    <visual>
      <origin rpy="0 0 0" xyz="0 0 0"/>
      <geometry>
        <box size="0.300 0.120 0.065"/>
      </geometry>
      <material name="blue">
        <color rgba="0.1 0.1 1.0 0.5"/>
      </material>
    </visual>
    <collision>
      <origin rpy="0 0 0" xyz="0 0 0"/>
      <geometry>
        <box size="0.300 0.120 0.065"/>
      </geometry>
      <material name="blue">
        <color rgba="0.1 0.1 1.0 0.5"/>
      </material>
    </collision>
    <inertial>
      <mass value="1"/>
      <inertia ixx="0.1" ixy="0.0" ixz="0.0" iyy="0.1" iyz="0.0" izz="0.1"/>
    </inertial>
  </link>
  <link name="plat_link">
    <visual>
      <origin rpy="0 0 0" xyz="0 0 0.0"/>
      <geometry>
        <box size="0.16 0.155 0.075"/>
      </geometry>
      <material name="blue">
        <color rgba="0.1 0.1 1.0 0.5"/>
      </material>
    </visual>
    <collision>
      <origin rpy="0 0 0" xyz="0 0 0"/>
      <geometry>
        <box size="0.16 0.155 0.075"/>
      </geometry>
      <material name="blue">
        <color rgba="0.1 0.1 1.0 0.5"/>
      </material>
    </collision>
    <inertial>
      <mass value="1"/>
      <inertia ixx="0.1" ixy="0.0" ixz="0.0" iyy="0.1" iyz="0.0" izz="0.1"/>
    </inertial>
  </link>
  <link name="laser_link">
    <visual>
      <origin rpy="0 0 0" xyz="0 0 0"/>
      <geometry>
        <cylinder length="0.02" radius="0.03"/>
      </geometry>
      <material name="black">
        <color rgba="0.0 0.0 0.0 0.5"/>
      </material>
    </visual>
    <collision>
      <origin rpy="0 0 0" xyz="0 0 0"/>
      <geometry>
        <cylinder length="0.02" radius="0.03"/>
      </geometry>
      <material name="black">
        <color rgba="0.0 0.0 0.0 0.5"/>
      </material>
    </collision>
    <inertial>
      <mass value="1"/>
      <inertia ixx="0.1" ixy="0.0" ixz="0.0" iyy="0.1" iyz="0.0" izz="0.1"/>
    </inertial>
  </link>
  <link name="tripod_link">
    <visual>
      <origin rpy="0 0 0" xyz="0 0 0"/>
      <geometry>
        <cylinder length="0.09" radius="0.035"/>
      </geometry>
      <material name="black">
        <color rgba="0.0 0.0 0.0 0.5"/>
      </material>
    </visual>
    <collision>
      <origin rpy="0 0 0" xyz="0 0 0"/>
      <geometry>
        <cylinder length="0.09" radius="0.035"/>
      </geometry>
      <material name="black">
        <color rgba="0.0 0.0 0.0 0.5"/>
      </material>
    </collision>
    <inertial>
      <mass value="1"/>
      <inertia ixx="0.1" ixy="0.0" ixz="0.0" iyy="0.1" iyz="0.0" izz="0.1"/>
    </inertial>
  </link>
  <!-- INTEL REALSENSE D435 -->
  <!-- INTEL REALSENSE R200 -->
  <!-- <xacro:macro name="realsense_R200" params="sensor_name parent_link rate *origin">

      <link name="${sensor_name}_R200_camera">
          <visual>
              <origin rpy="0 0 0" xyz="0 0 0"/>
              <geometry>
                  <mesh filename="package://realsense_ros2_gazebo/meshes/realsense_r200/meshes/realsense.dae"/>
              </geometry>
          </visual>
          <collision>
              <geometry>
                  <box size="0.0078 0.130 0.0192"/>
              </geometry>
          </collision>
          <inertial>
              <mass value="0.0615752"/>
              <origin rpy="0 0 0" xyz="0 0 0"/>
              <inertia ixx="9.108e-05"
                       ixy="0"
                       ixz="0"
                       iyy="2.51e-06"
                       iyz="0"
                       izz="8.931e-05"/>
          </inertial>
      </link>

      <joint name="${sensor_name}_joint" type="fixed">
          <parent link="${parent_link}"/>
          <child link="${sensor_name}_R200_camera"/>
          <xacro:insert_block name="origin"/>
      </joint>

      <link name="${sensor_name}_color" />
      <link name="${sensor_name}_depth" />
      <link name="${sensor_name}_ired1" />
      <link name="${sensor_name}_ired2" />

      <joint name="${sensor_name}_color_joint" type="fixed">
          <parent link="${sensor_name}_R200_camera" />
          <child link="${sensor_name}_color" />
          <origin xyz="0 -0.046 0.004" rpy="${pi/2} ${pi} ${pi/2}"/>
      </joint>

      <joint name="${sensor_name}_depth_joint" type="fixed">
          <parent link="${sensor_name}_R200_camera" />
          <child link="${sensor_name}_depth" />
          <origin xyz="0 -0.03 0.004" rpy="0 0 0"/>
      </joint>

      <joint name="${sensor_name}_ired1_joint" type="fixed">
          <parent link="${sensor_name}_R200_camera" />
          <child link="${sensor_name}_ired1" />
          <origin xyz="0 -0.06 0.004" rpy="0 0 0"/>
      </joint>

      <joint name="${sensor_name}_ired2_joint" type="fixed">
          <parent link="${sensor_name}_R200_camera" />
          <child link="${sensor_name}_ired2" />
          <origin xyz="0 0.01 0.004" rpy="0 0 0"/>
      </joint>


      <gazebo reference="${sensor_name}_R200_camera">

          <self_collide>0</self_collide>
          <enable_wind>0</enable_wind>
          <kinematic>0</kinematic>
          <gravity>1</gravity>
          <mu>1</mu>
          <mu2>1</mu2>
          <fdir1>0 0 0</fdir1>
          <slip1>0</slip1>
          <slip2>0</slip2>
          <kp>1e+13</kp>
          <kd>1</kd>
          <max_vel>0.01</max_vel>
          <min_depth>0</min_depth>

          <sensor name="${sensor_name}_color" type="camera">
              <pose frame="">0 -0.046 0.004 0 0 0</pose>
              <camera name="${sensor_name}_R200_camera">
              <horizontal_fov>1.047</horizontal_fov>
              <image>
                  <width>640</width>
                  <height>480</height>
                  <format>RGB_INT8</format>
              </image>
              <clip>
                  <near>0.1</near>
                  <far>100</far>
              </clip>
              <noise>
                  <type>gaussian</type>
                  <mean>0.0</mean>
                  <stddev>0.007</stddev>
              </noise>
              </camera>
              <always_on>1</always_on>
              <update_rate>${rate}</update_rate>
              <visualize>1</visualize>
          </sensor>
          <sensor name="${sensor_name}_ired1" type="camera">
              <pose frame="">0 -0.06 0.004 0 0 0</pose>
              <camera name="${sensor_name}_R200_camera">
              <horizontal_fov>1.047</horizontal_fov>
              <image>
                  <width>640</width>
                  <height>480</height>
                  <format>L_INT8</format>
              </image>
              <clip>
                  <near>0.1</near>
                  <far>100</far>
              </clip>
              <noise>
                  <type>gaussian</type>
                  <mean>0.0</mean>
                  <stddev>0.05</stddev>
              </noise>
              </camera>
              <always_on>1</always_on>
              <update_rate>${rate}</update_rate>
              <visualize>0</visualize>
          </sensor>
          <sensor name="${sensor_name}_ired2" type="camera">
              <pose frame="">0 0.01 0.004 0 0 0</pose>
              <camera name="${sensor_name}_R200_camera">
              <horizontal_fov>1.047</horizontal_fov>
              <image>
                  <width>640</width>
                  <height>480</height>
                  <format>L_INT8</format>
              </image>
              <clip>
                  <near>0.1</near>
                  <far>100</far>
              </clip>
              <noise>
                  <type>gaussian</type>
                  <mean>0.0</mean>
                  <stddev>0.05</stddev>
              </noise>
              </camera>
              <always_on>1</always_on>
              <update_rate>${rate}</update_rate>
              <visualize>0</visualize>
          </sensor>
          <sensor name="${sensor_name}_depth" type="depth">
              <pose frame="">0 -0.03 0.004 0 0 0</pose>
              <camera name="${sensor_name}_R200_camera">
              <horizontal_fov>1.047</horizontal_fov>
              <image>
                      <width>640</width>
                      <height>480</height>
              </image>
              <clip>
                      <near>0.1</near>
                      <far>100</far>
              </clip>
              <noise>
                      <type>gaussian</type>
                      <mean>0.0</mean>
                      <stddev>0.100</stddev>
              </noise>
              </camera>
              <always_on>1</always_on>
              <update_rate>60</update_rate>
              <visualize>0</visualize>
          </sensor>
      </gazebo>

      <gazebo>
        <plugin name="${sensor_name}" filename="librealsense_gazebo_plugin.so">
          <prefix>${sensor_name}_</prefix>
          <depthUpdateRate>${rate}</depthUpdateRate>
          <colorUpdateRate>${rate}</colorUpdateRate>
          <infraredUpdateRate>${rate}</infraredUpdateRate>
          <depthTopicName>depth/image_raw</depthTopicName>
          <depthCameraInfoTopicName>depth/camera_info</depthCameraInfoTopicName>
          <colorTopicName>color/image_raw</colorTopicName>
          <colorCameraInfoTopicName>color/camera_info</colorCameraInfoTopicName>
          <infrared1TopicName>infra1/image_raw</infrared1TopicName>
          <infrared1CameraInfoTopicName>infra1/camera_info</infrared1CameraInfoTopicName>
          <infrared2TopicName>infra2/image_raw</infrared2TopicName>
          <infrared2CameraInfoTopicName>infra2/camera_info</infrared2CameraInfoTopicName>
          <colorOpticalframeName>${sensor_name}_color_optical_frame</colorOpticalframeName>
          <depthOpticalframeName>${sensor_name}_depth_optical_frame</depthOpticalframeName>
          <infrared1OpticalframeName>${sensor_name}_infrared1_optical_frame</infrared1OpticalframeName>
          <infrared2OpticalframeName>${sensor_name}_infrared2_optical_frame</infrared2OpticalframeName>
          <rangeMinDepth>0.2</rangeMinDepth>
          <rangeMaxDepth>10.0</rangeMaxDepth>
          <pointCloud>false</pointCloud>
          <pointCloudTopicName>depth/color/points</pointCloudTopicName>
          <pointCloudCutoff>0.25</pointCloudCutoff>
          <pointCloudCutoffMax>9.0</pointCloudCutoffMax>
        </plugin>
      </gazebo>

  </xacro:macro> -->
  <!-- camera body, with origin at bottom screw mount -->
  <joint name="d435_joint" type="fixed">
    <origin rpy="0 0 0 " xyz="0 0 0.045"/>
    <parent link="tripod_link"/>
    <child link="d435_bottom_screw_frame"/>
  </joint>
  <link name="d435_bottom_screw_frame"/>
  <joint name="d435_link_joint" type="fixed">
    <origin rpy="0 0 0" xyz="0 0.0175 0.0125"/>
    <parent link="d435_bottom_screw_frame"/>
    <child link="d435_link"/>
  </joint>
  <link name="d435_link">
    <visual>
      <origin rpy="1.5707963267948966 0 1.5707963267948966" xyz="0.0149 -0.0175 0"/>
      <geometry>
        <mesh filename="file:///home/zj/pkg/realsense_ros2_gazebo/install/realsense_ros2_gazebo/share/realsense_ros2_gazebo/meshes/realsense_d435.stl"/>
      </geometry>
    </visual>
    <collision>
      <origin rpy="0 0 0" xyz="0 -0.0175 0"/>
      <geometry>
        <box size="0.02505 0.09 0.025"/>
      </geometry>
    </collision>
    <inertial>
      <mass value="0.564"/>
      <origin rpy="0 0 0" xyz="0 -0.0175 0"/>
      <inertia ixx="0.000410075" ixy="0" ixz="0" iyy="5.8867617499999996e-05" iyz="0" izz="5.8867617499999996e-05"/>
    </inertial>
  </link>
  <!-- camera depth joints and links -->
  <joint name="d435_depth_joint" type="fixed">
    <origin rpy="0 0 0" xyz="0 0 0"/>
    <parent link="d435_link"/>
    <child link="d435_depth_frame"/>
  </joint>
  <link name="d435_depth_frame"/>
  <joint name="d435_depth_optical_joint" type="fixed">
    <origin rpy="-1.5707963267948966 0 -1.5707963267948966" xyz="0 0 0"/>
    <parent link="d435_depth_frame"/>
    <child link="d435_depth_optical_frame"/>
  </joint>
  <link name="d435_depth_optical_frame"/>
  <!-- camera left IR joints and links -->
  <joint name="d435_left_ir_joint" type="fixed">
    <origin rpy="0 0 0" xyz="0 0.0 0"/>
    <parent link="d435_depth_frame"/>
    <child link="d435_left_ir_frame"/>
  </joint>
  <link name="d435_left_ir_frame"/>
  <joint name="d435_left_ir_optical_joint" type="fixed">
    <origin rpy="-1.5707963267948966 0 -1.5707963267948966" xyz="0 0 0"/>
    <parent link="d435_left_ir_frame"/>
    <child link="d435_left_ir_optical_frame"/>
  </joint>
  <link name="d435_left_ir_optical_frame"/>
  <!-- camera right IR joints and links -->
  <joint name="d435_right_ir_joint" type="fixed">
    <origin rpy="0 0 0" xyz="0 -0.05 0"/>
    <parent link="d435_depth_frame"/>
    <child link="d435_right_ir_frame"/>
  </joint>
  <link name="d435_right_ir_frame"/>
  <joint name="d435_right_ir_optical_joint" type="fixed">
    <origin rpy="-1.5707963267948966 0 -1.5707963267948966" xyz="0 0 0"/>
    <parent link="d435_right_ir_frame"/>
    <child link="d435_right_ir_optical_frame"/>
  </joint>
  <link name="d435_right_ir_optical_frame"/>
  <!-- camera color joints and links -->
  <joint name="d435_color_joint" type="fixed">
    <origin rpy="0 0 0" xyz="0 0.015 0"/>
    <parent link="d435_depth_frame"/>
    <child link="d435_color_frame"/>
  </joint>
  <link name="d435_color_frame"/>
  <joint name="d435_color_optical_joint" type="fixed">
    <origin rpy="-1.5707963267948966 0 -1.5707963267948966" xyz="0 0 0"/>
    <parent link="d435_color_frame"/>
    <child link="d435_color_optical_frame"/>
  </joint>
  <link name="d435_color_optical_frame"/>
  <!-- gazebo plugin -->
  <gazebo reference="d435_link">
    <self_collide>0</self_collide>
    <enable_wind>0</enable_wind>
    <kinematic>0</kinematic>
    <gravity>1</gravity>
    <mu2>1</mu2>
    <fdir1>0 0 0</fdir1>
    <kp>1e+13</kp>
    <kd>1</kd>
    <sensor name="d435_color" type="camera">
      <camera name="d435">
        <horizontal_fov>1.2112585008840648</horizontal_fov>
        <image>
          <width>640</width>
          <height>480</height>
          <format>RGB_INT8</format>
        </image>
        <clip>
          <near>0.1</near>
          <far>100</far>
        </clip>
        <noise>
          <type>gaussian</type>
          <mean>0.0</mean>
          <stddev>0.007</stddev>
        </noise>
      </camera>
      <always_on>1</always_on>
      <update_rate>30</update_rate>
      <visualize>1</visualize>
    </sensor>
    <sensor name="d435_ired1" type="camera">
      <camera name="d435">
        <horizontal_fov>1.4870205226991688</horizontal_fov>
        <image>
          <width>1280</width>
          <height>720</height>
          <format>L_INT8</format>
        </image>
        <clip>
          <near>0.1</near>
          <far>100</far>
        </clip>
        <noise>
          <type>gaussian</type>
          <mean>0.0</mean>
          <stddev>0.05</stddev>
        </noise>
      </camera>
      <always_on>1</always_on>
      <update_rate>90</update_rate>
      <visualize>0</visualize>
    </sensor>
    <sensor name="d435_ired2" type="camera">
      <camera name="d435">
        <horizontal_fov>1.4870205226991688</horizontal_fov>
        <image>
          <width>1280</width>
          <height>720</height>
          <format>L_INT8</format>
        </image>
        <clip>
          <near>0.1</near>
          <far>100</far>
        </clip>
        <noise>
          <type>gaussian</type>
          <mean>0.0</mean>
          <stddev>0.05</stddev>
        </noise>
      </camera>
      <always_on>1</always_on>
      <update_rate>90</update_rate>
      <visualize>0</visualize>
    </sensor>
    <sensor name="d435_depth" type="depth">
      <camera name="d435">
        <horizontal_fov>1.4870205226991688</horizontal_fov>
        <image>
          <width>1280</width>
          <height>720</height>
        </image>
        <clip>
          <near>0.1</near>
          <far>100</far>
        </clip>
        <noise>
          <type>gaussian</type>
          <mean>0.0</mean>
          <stddev>0.100</stddev>
        </noise>
      </camera>
      <always_on>1</always_on>
      <update_rate>90</update_rate>
      <visualize>0</visualize>
    </sensor>
  </gazebo>
  <gazebo>
    <plugin filename="librealsense_gazebo_plugin.so" name="d435">
      <prefix>d435_</prefix>
      <depthUpdateRate>30</depthUpdateRate>
      <colorUpdateRate>30</colorUpdateRate>
      <infraredUpdateRate>30</infraredUpdateRate>
      <depthTopicName>depth/image_raw</depthTopicName>
      <depthCameraInfoTopicName>depth/camera_info</depthCameraInfoTopicName>
      <colorTopicName>color/image_raw</colorTopicName>
      <colorCameraInfoTopicName>color/camera_info</colorCameraInfoTopicName>
      <infrared1TopicName>infra1/image_raw</infrared1TopicName>
      <infrared1CameraInfoTopicName>infra1/camera_info</infrared1CameraInfoTopicName>
      <infrared2TopicName>infra2/image_raw</infrared2TopicName>
      <infrared2CameraInfoTopicName>infra2/camera_info</infrared2CameraInfoTopicName>
      <colorOpticalframeName>d435_color_optical_frame</colorOpticalframeName>
      <depthOpticalframeName>d435_depth_optical_frame</depthOpticalframeName>
      <infrared1OpticalframeName>d435_infrared1_optical_frame</infrared1OpticalframeName>
      <infrared2OpticalframeName>d435_infrared2_optical_frame</infrared2OpticalframeName>
      <rangeMinDepth>0.2</rangeMinDepth>
      <rangeMaxDepth>10.0</rangeMaxDepth>
      <pointCloud>false</pointCloud>
      <pointCloudTopicName>depth/color/points</pointCloudTopicName>
      <pointCloudCutoff>0.25</pointCloudCutoff>
      <pointCloudCutoffMax>9.0</pointCloudCutoffMax>
    </plugin>
  </gazebo>
  <joint name="base_joint" type="fixed">
    <parent link="base_footprint"/>
    <child link="base_link"/>
    <origin rpy="0 0 0" xyz="0.0 0.0 0.1"/>
  </joint>
  <joint name="plat_joint" type="fixed">
    <parent link="base_link"/>
    <child link="plat_link"/>
    <origin rpy="0 0 0" xyz="-0.055 0.0 0.07"/>
  </joint>
  <joint name="laser_joint" type="fixed">
    <parent link="plat_link"/>
    <child link="laser_link"/>
    <origin rpy="0 0 0" xyz="0.055 0.0 0.05"/>
  </joint>
  <joint name="tripod_joint" type="fixed">
    <parent link="plat_link"/>
    <child link="tripod_link"/>
    <origin rpy="0 0 0" xyz="-0.03 0.0 0.08"/>
  </joint>
  <link name="left_front_link">
    <visual>
      <geometry>
        <cylinder length="0.05" radius="0.0275"/>
      </geometry>
      <origin rpy="1.5707963 0 0" xyz="0 0 0"/>
    </visual>
    <collision>
      <origin rpy="1.5707963 0 0" xyz="0 0 0"/>
      <geometry>
        <cylinder length="0.05" radius="0.0275"/>
      </geometry>
    </collision>
    <inertial>
      <mass value="1"/>
      <inertia ixx="0.1" ixy="0.0" ixz="0.0" iyy="0.1" iyz="0.0" izz="0.1"/>
    </inertial>
  </link>
  <joint name="left_front_joint" type="continuous">
    <parent link="base_link"/>
    <child link="left_front_link"/>
    <origin rpy="0 0 0" xyz="0.14 -0.095 -0.005"/>
    <axis xyz="0 1 0"/>
  </joint>
  <gazebo reference="left_front_link">
    <material>Gazebo/Gray</material>
  </gazebo>
  <link name="left0_link">
    <visual>
      <geometry>
        <cylinder length="0.05" radius="0.015"/>
      </geometry>
      <origin rpy="1.5707963 0 0" xyz="0 0 0"/>
    </visual>
    <collision>
      <origin rpy="1.5707963 0 0" xyz="0 0 0"/>
      <geometry>
        <cylinder length="0.05" radius="0.015"/>
      </geometry>
    </collision>
    <inertial>
      <mass value="1"/>
      <inertia ixx="0.1" ixy="0.0" ixz="0.0" iyy="0.1" iyz="0.0" izz="0.1"/>
    </inertial>
  </link>
  <joint name="left0_joint" type="continuous">
    <parent link="base_link"/>
    <child link="left0_link"/>
    <origin rpy="0 0 0" xyz="0.14 -0.095 -0.05"/>
    <axis xyz="0 1 0"/>
  </joint>
  <gazebo reference="left0_link">
    <material>Gazebo/Gray</material>
  </gazebo>
  <link name="left1_link">
    <visual>
      <geometry>
        <cylinder length="0.05" radius="0.015"/>
      </geometry>
      <origin rpy="1.5707963 0 0" xyz="0 0 0"/>
    </visual>
    <collision>
      <origin rpy="1.5707963 0 0" xyz="0 0 0"/>
      <geometry>
        <cylinder length="0.05" radius="0.015"/>
      </geometry>
    </collision>
    <inertial>
      <mass value="1"/>
      <inertia ixx="0.1" ixy="0.0" ixz="0.0" iyy="0.1" iyz="0.0" izz="0.1"/>
    </inertial>
  </link>
  <joint name="left1_joint" type="continuous">
    <parent link="base_link"/>
    <child link="left1_link"/>
    <origin rpy="0 0 0" xyz="0.075 -0.095 -0.05"/>
    <axis xyz="0 1 0"/>
  </joint>
  <gazebo reference="left1_link">
    <material>Gazebo/Gray</material>
  </gazebo>
  <link name="left2_link">
    <visual>
      <geometry>
        <cylinder length="0.05" radius="0.015"/>
      </geometry>
      <origin rpy="1.5707963 0 0" xyz="0 0 0"/>
    </visual>
    <collision>
      <origin rpy="1.5707963 0 0" xyz="0 0 0"/>
      <geometry>
        <cylinder length="0.05" radius="0.015"/>
      </geometry>
    </collision>
    <inertial>
      <mass value="1"/>
      <inertia ixx="0.1" ixy="0.0" ixz="0.0" iyy="0.1" iyz="0.0" izz="0.1"/>
    </inertial>
  </link>
  <joint name="left2_joint" type="continuous">
    <parent link="base_link"/>
    <child link="left2_link"/>
    <origin rpy="0 0 0" xyz="0.025 -0.095 -0.05"/>
    <axis xyz="0 1 0"/>
  </joint>
  <gazebo reference="left2_link">
    <material>Gazebo/Gray</material>
  </gazebo>
  <link name="left3_link">
    <visual>
      <geometry>
        <cylinder length="0.05" radius="0.015"/>
      </geometry>
      <origin rpy="1.5707963 0 0" xyz="0 0 0"/>
    </visual>
    <collision>
      <origin rpy="1.5707963 0 0" xyz="0 0 0"/>
      <geometry>
        <cylinder length="0.05" radius="0.015"/>
      </geometry>
    </collision>
    <inertial>
      <mass value="1"/>
      <inertia ixx="0.1" ixy="0.0" ixz="0.0" iyy="0.1" iyz="0.0" izz="0.1"/>
    </inertial>
  </link>
  <joint name="left3_joint" type="continuous">
    <parent link="base_link"/>
    <child link="left3_link"/>
    <origin rpy="0 0 0" xyz="-0.025 -0.095 -0.05"/>
    <axis xyz="0 1 0"/>
  </joint>
  <gazebo reference="left3_link">
    <material>Gazebo/Gray</material>
  </gazebo>
  <link name="left4_link">
    <visual>
      <geometry>
        <cylinder length="0.05" radius="0.015"/>
      </geometry>
      <origin rpy="1.5707963 0 0" xyz="0 0 0"/>
    </visual>
    <collision>
      <origin rpy="1.5707963 0 0" xyz="0 0 0"/>
      <geometry>
        <cylinder length="0.05" radius="0.015"/>
      </geometry>
    </collision>
    <inertial>
      <mass value="1"/>
      <inertia ixx="0.1" ixy="0.0" ixz="0.0" iyy="0.1" iyz="0.0" izz="0.1"/>
    </inertial>
  </link>
  <joint name="left4_joint" type="continuous">
    <parent link="base_link"/>
    <child link="left4_link"/>
    <origin rpy="0 0 0" xyz="-0.075 -0.095 -0.05"/>
    <axis xyz="0 1 0"/>
  </joint>
  <gazebo reference="left4_link">
    <material>Gazebo/Gray</material>
  </gazebo>
  <link name="left5_link">
    <visual>
      <geometry>
        <cylinder length="0.05" radius="0.015"/>
      </geometry>
      <origin rpy="1.5707963 0 0" xyz="0 0 0"/>
    </visual>
    <collision>
      <origin rpy="1.5707963 0 0" xyz="0 0 0"/>
      <geometry>
        <cylinder length="0.05" radius="0.015"/>
      </geometry>
    </collision>
    <inertial>
      <mass value="1"/>
      <inertia ixx="0.1" ixy="0.0" ixz="0.0" iyy="0.1" iyz="0.0" izz="0.1"/>
    </inertial>
  </link>
  <joint name="left5_joint" type="continuous">
    <parent link="base_link"/>
    <child link="left5_link"/>
    <origin rpy="0 0 0" xyz="-0.125 -0.095 -0.05"/>
    <axis xyz="0 1 0"/>
  </joint>
  <gazebo reference="left5_link">
    <material>Gazebo/Gray</material>
  </gazebo>
  <link name="left_back_link">
    <visual>
      <geometry>
        <cylinder length="0.05" radius="0.0275"/>
      </geometry>
      <origin rpy="1.5707963 0 0" xyz="0 0 0"/>
    </visual>
    <collision>
      <origin rpy="1.5707963 0 0" xyz="0 0 0"/>
      <geometry>
        <cylinder length="0.05" radius="0.0275"/>
      </geometry>
    </collision>
    <inertial>
      <mass value="1"/>
      <inertia ixx="0.1" ixy="0.0" ixz="0.0" iyy="0.1" iyz="0.0" izz="0.1"/>
    </inertial>
  </link>
  <joint name="left_back_joint" type="continuous">
    <parent link="base_link"/>
    <child link="left_back_link"/>
    <origin rpy="0 0 0" xyz="-0.125 -0.095 -0.005"/>
    <axis xyz="0 1 0"/>
  </joint>
  <gazebo reference="left_back_link">
    <material>Gazebo/Gray</material>
  </gazebo>
  <link name="right_front_link">
    <visual>
      <geometry>
        <cylinder length="0.05" radius="0.0275"/>
      </geometry>
      <origin rpy="1.5707963 0 0" xyz="0 0 0"/>
    </visual>
    <collision>
      <origin rpy="1.5707963 0 0" xyz="0 0 0"/>
      <geometry>
        <cylinder length="0.05" radius="0.0275"/>
      </geometry>
    </collision>
    <inertial>
      <mass value="1"/>
      <inertia ixx="0.1" ixy="0.0" ixz="0.0" iyy="0.1" iyz="0.0" izz="0.1"/>
    </inertial>
  </link>
  <joint name="right_front_joint" type="continuous">
    <parent link="base_link"/>
    <child link="right_front_link"/>
    <origin rpy="0 0 0" xyz="0.14 0.095 -0.005"/>
    <axis xyz="0 1 0"/>
  </joint>
  <gazebo reference="right_front_link">
    <material>Gazebo/Gray</material>
  </gazebo>
  <link name="right0_link">
    <visual>
      <geometry>
        <cylinder length="0.05" radius="0.015"/>
      </geometry>
      <origin rpy="1.5707963 0 0" xyz="0 0 0"/>
    </visual>
    <collision>
      <origin rpy="1.5707963 0 0" xyz="0 0 0"/>
      <geometry>
        <cylinder length="0.05" radius="0.015"/>
      </geometry>
    </collision>
    <inertial>
      <mass value="1"/>
      <inertia ixx="0.1" ixy="0.0" ixz="0.0" iyy="0.1" iyz="0.0" izz="0.1"/>
    </inertial>
  </link>
  <joint name="right0_joint" type="continuous">
    <parent link="base_link"/>
    <child link="right0_link"/>
    <origin rpy="0 0 0" xyz="0.14 0.095 -0.05"/>
    <axis xyz="0 1 0"/>
  </joint>
  <gazebo reference="right0_link">
    <material>Gazebo/Gray</material>
  </gazebo>
  <link name="right1_link">
    <visual>
      <geometry>
        <cylinder length="0.05" radius="0.015"/>
      </geometry>
      <origin rpy="1.5707963 0 0" xyz="0 0 0"/>
    </visual>
    <collision>
      <origin rpy="1.5707963 0 0" xyz="0 0 0"/>
      <geometry>
        <cylinder length="0.05" radius="0.015"/>
      </geometry>
    </collision>
    <inertial>
      <mass value="1"/>
      <inertia ixx="0.1" ixy="0.0" ixz="0.0" iyy="0.1" iyz="0.0" izz="0.1"/>
    </inertial>
  </link>
  <joint name="right1_joint" type="continuous">
    <parent link="base_link"/>
    <child link="right1_link"/>
    <origin rpy="0 0 0" xyz="0.075 0.095 -0.05"/>
    <axis xyz="0 1 0"/>
  </joint>
  <gazebo reference="right1_link">
    <material>Gazebo/Gray</material>
  </gazebo>
  <link name="right2_link">
    <visual>
      <geometry>
        <cylinder length="0.05" radius="0.015"/>
      </geometry>
      <origin rpy="1.5707963 0 0" xyz="0 0 0"/>
    </visual>
    <collision>
      <origin rpy="1.5707963 0 0" xyz="0 0 0"/>
      <geometry>
        <cylinder length="0.05" radius="0.015"/>
      </geometry>
    </collision>
    <inertial>
      <mass value="1"/>
      <inertia ixx="0.1" ixy="0.0" ixz="0.0" iyy="0.1" iyz="0.0" izz="0.1"/>
    </inertial>
  </link>
  <joint name="right2_joint" type="continuous">
    <parent link="base_link"/>
    <child link="right2_link"/>
    <origin rpy="0 0 0" xyz="0.025 0.095 -0.05"/>
    <axis xyz="0 1 0"/>
  </joint>
  <gazebo reference="right2_link">
    <material>Gazebo/Gray</material>
  </gazebo>
  <link name="right3_link">
    <visual>
      <geometry>
        <cylinder length="0.05" radius="0.015"/>
      </geometry>
      <origin rpy="1.5707963 0 0" xyz="0 0 0"/>
    </visual>
    <collision>
      <origin rpy="1.5707963 0 0" xyz="0 0 0"/>
      <geometry>
        <cylinder length="0.05" radius="0.015"/>
      </geometry>
    </collision>
    <inertial>
      <mass value="1"/>
      <inertia ixx="0.1" ixy="0.0" ixz="0.0" iyy="0.1" iyz="0.0" izz="0.1"/>
    </inertial>
  </link>
  <joint name="right3_joint" type="continuous">
    <parent link="base_link"/>
    <child link="right3_link"/>
    <origin rpy="0 0 0" xyz="-0.025 0.095 -0.05"/>
    <axis xyz="0 1 0"/>
  </joint>
  <gazebo reference="right3_link">
    <material>Gazebo/Gray</material>
  </gazebo>
  <link name="right4_link">
    <visual>
      <geometry>
        <cylinder length="0.05" radius="0.015"/>
      </geometry>
      <origin rpy="1.5707963 0 0" xyz="0 0 0"/>
    </visual>
    <collision>
      <origin rpy="1.5707963 0 0" xyz="0 0 0"/>
      <geometry>
        <cylinder length="0.05" radius="0.015"/>
      </geometry>
    </collision>
    <inertial>
      <mass value="1"/>
      <inertia ixx="0.1" ixy="0.0" ixz="0.0" iyy="0.1" iyz="0.0" izz="0.1"/>
    </inertial>
  </link>
  <joint name="right4_joint" type="continuous">
    <parent link="base_link"/>
    <child link="right4_link"/>
    <origin rpy="0 0 0" xyz="-0.075 0.095 -0.05"/>
    <axis xyz="0 1 0"/>
  </joint>
  <gazebo reference="right4_link">
    <material>Gazebo/Gray</material>
  </gazebo>
  <link name="right5_link">
    <visual>
      <geometry>
        <cylinder length="0.05" radius="0.015"/>
      </geometry>
      <origin rpy="1.5707963 0 0" xyz="0 0 0"/>
    </visual>
    <collision>
      <origin rpy="1.5707963 0 0" xyz="0 0 0"/>
      <geometry>
        <cylinder length="0.05" radius="0.015"/>
      </geometry>
    </collision>
    <inertial>
      <mass value="1"/>
      <inertia ixx="0.1" ixy="0.0" ixz="0.0" iyy="0.1" iyz="0.0" izz="0.1"/>
    </inertial>
  </link>
  <joint name="right5_joint" type="continuous">
    <parent link="base_link"/>
    <child link="right5_link"/>
    <origin rpy="0 0 0" xyz="-0.125 0.095 -0.05"/>
    <axis xyz="0 1 0"/>
  </joint>
  <gazebo reference="right5_link">
    <material>Gazebo/Gray</material>
  </gazebo>
  <link name="right_back_link">
    <visual>
      <geometry>
        <cylinder length="0.05" radius="0.0275"/>
      </geometry>
      <origin rpy="1.5707963 0 0" xyz="0 0 0"/>
    </visual>
    <collision>
      <origin rpy="1.5707963 0 0" xyz="0 0 0"/>
      <geometry>
        <cylinder length="0.05" radius="0.0275"/>
      </geometry>
    </collision>
    <inertial>
      <mass value="1"/>
      <inertia ixx="0.1" ixy="0.0" ixz="0.0" iyy="0.1" iyz="0.0" izz="0.1"/>
    </inertial>
  </link>
  <joint name="right_back_joint" type="continuous">
    <parent link="base_link"/>
    <child link="right_back_link"/>
    <origin rpy="0 0 0" xyz="-0.125 0.095 -0.005"/>
    <axis xyz="0 1 0"/>
  </joint>
  <gazebo reference="right_back_link">
    <material>Gazebo/Gray</material>
  </gazebo>
  <gazebo reference="base_link">
    <material>Gazebo/Green</material>
  </gazebo>
  <gazebo reference="plat_link">
    <material>Gazebo/Black</material>
  </gazebo>
  <gazebo reference="laser_link">
    <material>Gazebo/Gray</material>
  </gazebo>
  <gazebo reference="tripod_link">
    <material>Gazebo/Gray</material>
  </gazebo>
  <gazebo>
    <plugin filename="libgazebo_ros_planar_move.so" name="diff_drive">
      <leftFrontJoint>left0_joint</leftFrontJoint>
      <rightFrontJoint>right0_joint</rightFrontJoint>
      <leftRearJoint>left5_joint</leftRearJoint>
      <rightRearJoint>right5_joint</rightRearJoint>
      <commandTopic>cmd_vel</commandTopic>
      <odometryTopic>odom</odometryTopic>
      <odometryFrame>odom</odometryFrame>
      <robotNamespace>/</robotNamespace>
      <odometryRate>10.0</odometryRate>
      <publish_odom>true</publish_odom>
      <publish_odom_tf>true</publish_odom_tf>
      <publish_wheel_tf>true</publish_wheel_tf>
      <robotBaseFrame>base_footprint</robotBaseFrame>
    </plugin>
  </gazebo>
  <gazebo reference="laser_link">
    <sensor name="laser_sensor" type="ray">
      <always_on>true</always_on>
      <visualize>false</visualize>
      <update_rate>10</update_rate>
      <pose>0 0 0.075 0 0 0</pose>
      <ray>
        <scan>
          <horizontal>
            <samples>360</samples>
            <resolution>1.000000</resolution>
            <min_angle>0.00</min_angle>
            <max_angle>6.28</max_angle>
          </horizontal>
        </scan>
        <range>
          <min>0.200000</min>
          <max>50</max>
          <resolution>0.005000</resolution>
        </range>
        <noise>
          <type>gaussian</type>
          <mean>0.0</mean>
          <stddev>0.001</stddev>
        </noise>
      </ray>
      <plugin filename="libgazebo_ros_ray_sensor.so" name="laserscan">
        <robotNamespace>/</robotNamespace>
        <ros>
          <remapping>~/out:=scan</remapping>
        </ros>
        <output_type>sensor_msgs/LaserScan</output_type>
        <frame_name>laser_link</frame_name>
      </plugin>
    </sensor>
  </gazebo>
</robot>
