<?xml version="1.0" ?>
<!-- =================================================================================== -->
<!-- |    This document was autogenerated by xacro from caterpillar_robot.xacro        | -->
<!-- |    EDITING THIS FILE BY HAND IS NOT RECOMMENDED                                 | -->
<!-- =================================================================================== -->
<robot name="mycar">
  <material name="aluminum">
    <color rgba="0.5 0.5 0.5 1"/>
  </material>
  <material name="plastic">
    <color rgba="0.1 0.1 0.1 1"/>
  </material>
  <link name="base_footprint"/>
  <link name="base_link">
    <visual>
      <origin rpy="0 0 0" xyz="0 0 0"/>
      <geometry>
        <box size="0.300 0.120 0.065"/>
      </geometry>
      <material name="blue">
        <color rgba="0.1 0.1 1.0 0.5"/>
      </material>
    </visual>
    <collision>
      <origin rpy="0 0 0" xyz="0 0 0"/>
      <geometry>
        <box size="0.300 0.120 0.065"/>
      </geometry>
      <material name="blue">
        <color rgba="0.1 0.1 1.0 0.5"/>
      </material>
    </collision>
    <inertial>
      <mass value="1"/>
      <inertia ixx="0.1" ixy="0.0" ixz="0.0" iyy="0.1" iyz="0.0" izz="0.1"/>
    </inertial>
  </link>
  <link name="plat_link">
    <visual>
      <origin rpy="0 0 0" xyz="0 0 0.0"/>
      <geometry>
        <box size="0.16 0.155 0.075"/>
      </geometry>
      <material name="blue">
        <color rgba="0.1 0.1 1.0 0.5"/>
      </material>
    </visual>
    <collision>
      <origin rpy="0 0 0" xyz="0 0 0"/>
      <geometry>
        <box size="0.16 0.155 0.075"/>
      </geometry>
      <material name="blue">
        <color rgba="0.1 0.1 1.0 0.5"/>
      </material>
    </collision>
    <inertial>
      <mass value="1"/>
      <inertia ixx="0.1" ixy="0.0" ixz="0.0" iyy="0.1" iyz="0.0" izz="0.1"/>
    </inertial>
  </link>
  <link name="laser_link">
    <visual>
      <origin rpy="0 0 0" xyz="0 0 0"/>
      <geometry>
        <cylinder length="0.02" radius="0.03"/>
      </geometry>
      <material name="black">
        <color rgba="0.0 0.0 0.0 0.5"/>
      </material>
    </visual>
    <collision>
      <origin rpy="0 0 0" xyz="0 0 0"/>
      <geometry>
        <cylinder length="0.02" radius="0.03"/>
      </geometry>
      <material name="black">
        <color rgba="0.0 0.0 0.0 0.5"/>
      </material>
    </collision>
    <inertial>
      <mass value="1"/>
      <inertia ixx="0.1" ixy="0.0" ixz="0.0" iyy="0.1" iyz="0.0" izz="0.1"/>
    </inertial>
  </link>
  <link name="tripod_link">
    <visual>
      <origin rpy="0 0 0" xyz="0 0 0"/>
      <geometry>
        <cylinder length="0.09" radius="0.035"/>
      </geometry>
      <material name="black">
        <color rgba="0.0 0.0 0.0 0.5"/>
      </material>
    </visual>
    <collision>
      <origin rpy="0 0 0" xyz="0 0 0"/>
      <geometry>
        <cylinder length="0.09" radius="0.035"/>
      </geometry>
      <material name="black">
        <color rgba="0.0 0.0 0.0 0.5"/>
      </material>
    </collision>
    <inertial>
      <mass value="1"/>
      <inertia ixx="0.1" ixy="0.0" ixz="0.0" iyy="0.1" iyz="0.0" izz="0.1"/>
    </inertial>
  </link>
  <!-- camera body, with origin at bottom screw mount -->
  <joint name="camera_joint" type="fixed">
    <origin rpy="0 0 0" xyz="0 0 0.06"/>
    <parent link="tripod_link"/>
    <child link="camera_bottom_screw_frame"/>
  </joint>
  <link name="camera_bottom_screw_frame"/>
  <joint name="camera_link_joint" type="fixed">
    <origin rpy="0 0 0" xyz="0.010600000000000002 0.0175 0.0125"/>
    <parent link="camera_bottom_screw_frame"/>
    <child link="camera_link"/>
  </joint>
  <link name="camera_link">
    <visual>
      <!-- the mesh origin is at front plate in between the two infrared camera axes -->
      <origin rpy="1.5707963267948966 0 1.5707963267948966" xyz="0.0043 -0.0175 0"/>
      <geometry>
        <mesh filename="package://realsense2_description/meshes/d435.dae"/>
      </geometry>
    </visual>
    <collision>
      <origin rpy="0 0 0" xyz="0 -0.0175 0"/>
      <geometry>
        <box size="0.02505 0.09 0.025"/>
      </geometry>
    </collision>
    <inertial>
      <!-- The following are not reliable values, and should not be used for modeling -->
      <mass value="0.072"/>
      <origin xyz="0 0 0"/>
      <inertia ixx="0.003881243" ixy="0.0" ixz="0.0" iyy="0.000498940" iyz="0.0" izz="0.003879257"/>
    </inertial>
  </link>
  <joint name="base_joint" type="fixed">
    <parent link="base_footprint"/>
    <child link="base_link"/>
    <origin rpy="0 0 0" xyz="0.0 0.0 0.1"/>
  </joint>
  <joint name="plat_joint" type="fixed">
    <parent link="base_link"/>
    <child link="plat_link"/>
    <origin rpy="0 0 0" xyz="-0.055 0.0 0.07"/>
  </joint>
  <joint name="laser_joint" type="fixed">
    <parent link="plat_link"/>
    <child link="laser_link"/>
    <origin rpy="0 0 0" xyz="0.055 0.0 0.05"/>
  </joint>
  <joint name="tripod_joint" type="fixed">
    <parent link="plat_link"/>
    <child link="tripod_link"/>
    <origin rpy="0 0 0" xyz="-0.03 0.0 0.08"/>
  </joint>
  <!-- <joint name="camera_joint" type="continuous">
        <parent link="tripod_link"/>
        <child link="camera_link"/>
        <origin xyz="0 0.0 0.06" rpy="0 0 0"/>
    </joint> -->
  <link name="left_front_link">
    <visual>
      <geometry>
        <cylinder length="0.05" radius="0.0275"/>
      </geometry>
      <origin rpy="1.5707963 0 0" xyz="0 0 0"/>
    </visual>
    <collision>
      <origin rpy="1.5707963 0 0" xyz="0 0 0"/>
      <geometry>
        <cylinder length="0.05" radius="0.0275"/>
      </geometry>
      <!-- <surface>
                    <friction>
                        <ode mu="${mu}" mu2="${mu2}"/>
                    </friction>
                </surface> -->
    </collision>
    <inertial>
      <mass value="1"/>
      <inertia ixx="0.1" ixy="0.0" ixz="0.0" iyy="0.1" iyz="0.0" izz="0.1"/>
    </inertial>
  </link>
  <joint name="left_front_joint" type="continuous">
    <parent link="base_link"/>
    <child link="left_front_link"/>
    <origin rpy="0 0 0" xyz="0.14 -0.095 -0.005"/>
    <axis xyz="0 1 0"/>
  </joint>
  <gazebo reference="left_front_link">
    <material>Gazebo/Gray</material>
  </gazebo>
  <link name="left0_link">
    <visual>
      <geometry>
        <cylinder length="0.05" radius="0.015"/>
      </geometry>
      <origin rpy="1.5707963 0 0" xyz="0 0 0"/>
    </visual>
    <collision>
      <origin rpy="1.5707963 0 0" xyz="0 0 0"/>
      <geometry>
        <cylinder length="0.05" radius="0.015"/>
      </geometry>
      <!-- <surface>
                    <friction>
                        <ode mu="${mu}" mu2="${mu2}"/>
                    </friction>
                </surface> -->
    </collision>
    <inertial>
      <mass value="1"/>
      <inertia ixx="0.1" ixy="0.0" ixz="0.0" iyy="0.1" iyz="0.0" izz="0.1"/>
    </inertial>
  </link>
  <joint name="left0_joint" type="continuous">
    <parent link="base_link"/>
    <child link="left0_link"/>
    <origin rpy="0 0 0" xyz="0.14 -0.095 -0.05"/>
    <axis xyz="0 1 0"/>
  </joint>
  <gazebo reference="left0_link">
    <material>Gazebo/Gray</material>
  </gazebo>
  <link name="left1_link">
    <visual>
      <geometry>
        <cylinder length="0.05" radius="0.015"/>
      </geometry>
      <origin rpy="1.5707963 0 0" xyz="0 0 0"/>
    </visual>
    <collision>
      <origin rpy="1.5707963 0 0" xyz="0 0 0"/>
      <geometry>
        <cylinder length="0.05" radius="0.015"/>
      </geometry>
      <!-- <surface>
                    <friction>
                        <ode mu="${mu}" mu2="${mu2}"/>
                    </friction>
                </surface> -->
    </collision>
    <inertial>
      <mass value="1"/>
      <inertia ixx="0.1" ixy="0.0" ixz="0.0" iyy="0.1" iyz="0.0" izz="0.1"/>
    </inertial>
  </link>
  <joint name="left1_joint" type="continuous">
    <parent link="base_link"/>
    <child link="left1_link"/>
    <origin rpy="0 0 0" xyz="0.075 -0.095 -0.05"/>
    <axis xyz="0 1 0"/>
  </joint>
  <gazebo reference="left1_link">
    <material>Gazebo/Gray</material>
  </gazebo>
  <link name="left2_link">
    <visual>
      <geometry>
        <cylinder length="0.05" radius="0.015"/>
      </geometry>
      <origin rpy="1.5707963 0 0" xyz="0 0 0"/>
    </visual>
    <collision>
      <origin rpy="1.5707963 0 0" xyz="0 0 0"/>
      <geometry>
        <cylinder length="0.05" radius="0.015"/>
      </geometry>
      <!-- <surface>
                    <friction>
                        <ode mu="${mu}" mu2="${mu2}"/>
                    </friction>
                </surface> -->
    </collision>
    <inertial>
      <mass value="1"/>
      <inertia ixx="0.1" ixy="0.0" ixz="0.0" iyy="0.1" iyz="0.0" izz="0.1"/>
    </inertial>
  </link>
  <joint name="left2_joint" type="continuous">
    <parent link="base_link"/>
    <child link="left2_link"/>
    <origin rpy="0 0 0" xyz="0.025 -0.095 -0.05"/>
    <axis xyz="0 1 0"/>
  </joint>
  <gazebo reference="left2_link">
    <material>Gazebo/Gray</material>
  </gazebo>
  <link name="left3_link">
    <visual>
      <geometry>
        <cylinder length="0.05" radius="0.015"/>
      </geometry>
      <origin rpy="1.5707963 0 0" xyz="0 0 0"/>
    </visual>
    <collision>
      <origin rpy="1.5707963 0 0" xyz="0 0 0"/>
      <geometry>
        <cylinder length="0.05" radius="0.015"/>
      </geometry>
      <!-- <surface>
                    <friction>
                        <ode mu="${mu}" mu2="${mu2}"/>
                    </friction>
                </surface> -->
    </collision>
    <inertial>
      <mass value="1"/>
      <inertia ixx="0.1" ixy="0.0" ixz="0.0" iyy="0.1" iyz="0.0" izz="0.1"/>
    </inertial>
  </link>
  <joint name="left3_joint" type="continuous">
    <parent link="base_link"/>
    <child link="left3_link"/>
    <origin rpy="0 0 0" xyz="-0.025 -0.095 -0.05"/>
    <axis xyz="0 1 0"/>
  </joint>
  <gazebo reference="left3_link">
    <material>Gazebo/Gray</material>
  </gazebo>
  <link name="left4_link">
    <visual>
      <geometry>
        <cylinder length="0.05" radius="0.015"/>
      </geometry>
      <origin rpy="1.5707963 0 0" xyz="0 0 0"/>
    </visual>
    <collision>
      <origin rpy="1.5707963 0 0" xyz="0 0 0"/>
      <geometry>
        <cylinder length="0.05" radius="0.015"/>
      </geometry>
      <!-- <surface>
                    <friction>
                        <ode mu="${mu}" mu2="${mu2}"/>
                    </friction>
                </surface> -->
    </collision>
    <inertial>
      <mass value="1"/>
      <inertia ixx="0.1" ixy="0.0" ixz="0.0" iyy="0.1" iyz="0.0" izz="0.1"/>
    </inertial>
  </link>
  <joint name="left4_joint" type="continuous">
    <parent link="base_link"/>
    <child link="left4_link"/>
    <origin rpy="0 0 0" xyz="-0.075 -0.095 -0.05"/>
    <axis xyz="0 1 0"/>
  </joint>
  <gazebo reference="left4_link">
    <material>Gazebo/Gray</material>
  </gazebo>
  <link name="left5_link">
    <visual>
      <geometry>
        <cylinder length="0.05" radius="0.015"/>
      </geometry>
      <origin rpy="1.5707963 0 0" xyz="0 0 0"/>
    </visual>
    <collision>
      <origin rpy="1.5707963 0 0" xyz="0 0 0"/>
      <geometry>
        <cylinder length="0.05" radius="0.015"/>
      </geometry>
      <!-- <surface>
                    <friction>
                        <ode mu="${mu}" mu2="${mu2}"/>
                    </friction>
                </surface> -->
    </collision>
    <inertial>
      <mass value="1"/>
      <inertia ixx="0.1" ixy="0.0" ixz="0.0" iyy="0.1" iyz="0.0" izz="0.1"/>
    </inertial>
  </link>
  <joint name="left5_joint" type="continuous">
    <parent link="base_link"/>
    <child link="left5_link"/>
    <origin rpy="0 0 0" xyz="-0.125 -0.095 -0.05"/>
    <axis xyz="0 1 0"/>
  </joint>
  <gazebo reference="left5_link">
    <material>Gazebo/Gray</material>
  </gazebo>
  <link name="left_back_link">
    <visual>
      <geometry>
        <cylinder length="0.05" radius="0.0275"/>
      </geometry>
      <origin rpy="1.5707963 0 0" xyz="0 0 0"/>
    </visual>
    <collision>
      <origin rpy="1.5707963 0 0" xyz="0 0 0"/>
      <geometry>
        <cylinder length="0.05" radius="0.0275"/>
      </geometry>
      <!-- <surface>
                    <friction>
                        <ode mu="${mu}" mu2="${mu2}"/>
                    </friction>
                </surface> -->
    </collision>
    <inertial>
      <mass value="1"/>
      <inertia ixx="0.1" ixy="0.0" ixz="0.0" iyy="0.1" iyz="0.0" izz="0.1"/>
    </inertial>
  </link>
  <joint name="left_back_joint" type="continuous">
    <parent link="base_link"/>
    <child link="left_back_link"/>
    <origin rpy="0 0 0" xyz="-0.125 -0.095 -0.005"/>
    <axis xyz="0 1 0"/>
  </joint>
  <gazebo reference="left_back_link">
    <material>Gazebo/Gray</material>
  </gazebo>
  <!-- <xacro:wheel_func wheel_name="leftv" xyz="-0.1 -0.15 -0.04" rpy="0 0 0" radius="0.0275" length="0.05" mu="4" mu2="4"/> -->
  <link name="right_front_link">
    <visual>
      <geometry>
        <cylinder length="0.05" radius="0.0275"/>
      </geometry>
      <origin rpy="1.5707963 0 0" xyz="0 0 0"/>
    </visual>
    <collision>
      <origin rpy="1.5707963 0 0" xyz="0 0 0"/>
      <geometry>
        <cylinder length="0.05" radius="0.0275"/>
      </geometry>
      <!-- <surface>
                    <friction>
                        <ode mu="${mu}" mu2="${mu2}"/>
                    </friction>
                </surface> -->
    </collision>
    <inertial>
      <mass value="1"/>
      <inertia ixx="0.1" ixy="0.0" ixz="0.0" iyy="0.1" iyz="0.0" izz="0.1"/>
    </inertial>
  </link>
  <joint name="right_front_joint" type="continuous">
    <parent link="base_link"/>
    <child link="right_front_link"/>
    <origin rpy="0 0 0" xyz="0.14 0.095 -0.005"/>
    <axis xyz="0 1 0"/>
  </joint>
  <gazebo reference="right_front_link">
    <material>Gazebo/Gray</material>
  </gazebo>
  <link name="right0_link">
    <visual>
      <geometry>
        <cylinder length="0.05" radius="0.015"/>
      </geometry>
      <origin rpy="1.5707963 0 0" xyz="0 0 0"/>
    </visual>
    <collision>
      <origin rpy="1.5707963 0 0" xyz="0 0 0"/>
      <geometry>
        <cylinder length="0.05" radius="0.015"/>
      </geometry>
      <!-- <surface>
                    <friction>
                        <ode mu="${mu}" mu2="${mu2}"/>
                    </friction>
                </surface> -->
    </collision>
    <inertial>
      <mass value="1"/>
      <inertia ixx="0.1" ixy="0.0" ixz="0.0" iyy="0.1" iyz="0.0" izz="0.1"/>
    </inertial>
  </link>
  <joint name="right0_joint" type="continuous">
    <parent link="base_link"/>
    <child link="right0_link"/>
    <origin rpy="0 0 0" xyz="0.14 0.095 -0.05"/>
    <axis xyz="0 1 0"/>
  </joint>
  <gazebo reference="right0_link">
    <material>Gazebo/Gray</material>
  </gazebo>
  <link name="right1_link">
    <visual>
      <geometry>
        <cylinder length="0.05" radius="0.015"/>
      </geometry>
      <origin rpy="1.5707963 0 0" xyz="0 0 0"/>
    </visual>
    <collision>
      <origin rpy="1.5707963 0 0" xyz="0 0 0"/>
      <geometry>
        <cylinder length="0.05" radius="0.015"/>
      </geometry>
      <!-- <surface>
                    <friction>
                        <ode mu="${mu}" mu2="${mu2}"/>
                    </friction>
                </surface> -->
    </collision>
    <inertial>
      <mass value="1"/>
      <inertia ixx="0.1" ixy="0.0" ixz="0.0" iyy="0.1" iyz="0.0" izz="0.1"/>
    </inertial>
  </link>
  <joint name="right1_joint" type="continuous">
    <parent link="base_link"/>
    <child link="right1_link"/>
    <origin rpy="0 0 0" xyz="0.075 0.095 -0.05"/>
    <axis xyz="0 1 0"/>
  </joint>
  <gazebo reference="right1_link">
    <material>Gazebo/Gray</material>
  </gazebo>
  <link name="right2_link">
    <visual>
      <geometry>
        <cylinder length="0.05" radius="0.015"/>
      </geometry>
      <origin rpy="1.5707963 0 0" xyz="0 0 0"/>
    </visual>
    <collision>
      <origin rpy="1.5707963 0 0" xyz="0 0 0"/>
      <geometry>
        <cylinder length="0.05" radius="0.015"/>
      </geometry>
      <!-- <surface>
                    <friction>
                        <ode mu="${mu}" mu2="${mu2}"/>
                    </friction>
                </surface> -->
    </collision>
    <inertial>
      <mass value="1"/>
      <inertia ixx="0.1" ixy="0.0" ixz="0.0" iyy="0.1" iyz="0.0" izz="0.1"/>
    </inertial>
  </link>
  <joint name="right2_joint" type="continuous">
    <parent link="base_link"/>
    <child link="right2_link"/>
    <origin rpy="0 0 0" xyz="0.025 0.095 -0.05"/>
    <axis xyz="0 1 0"/>
  </joint>
  <gazebo reference="right2_link">
    <material>Gazebo/Gray</material>
  </gazebo>
  <link name="right3_link">
    <visual>
      <geometry>
        <cylinder length="0.05" radius="0.015"/>
      </geometry>
      <origin rpy="1.5707963 0 0" xyz="0 0 0"/>
    </visual>
    <collision>
      <origin rpy="1.5707963 0 0" xyz="0 0 0"/>
      <geometry>
        <cylinder length="0.05" radius="0.015"/>
      </geometry>
      <!-- <surface>
                    <friction>
                        <ode mu="${mu}" mu2="${mu2}"/>
                    </friction>
                </surface> -->
    </collision>
    <inertial>
      <mass value="1"/>
      <inertia ixx="0.1" ixy="0.0" ixz="0.0" iyy="0.1" iyz="0.0" izz="0.1"/>
    </inertial>
  </link>
  <joint name="right3_joint" type="continuous">
    <parent link="base_link"/>
    <child link="right3_link"/>
    <origin rpy="0 0 0" xyz="-0.025 0.095 -0.05"/>
    <axis xyz="0 1 0"/>
  </joint>
  <gazebo reference="right3_link">
    <material>Gazebo/Gray</material>
  </gazebo>
  <link name="right4_link">
    <visual>
      <geometry>
        <cylinder length="0.05" radius="0.015"/>
      </geometry>
      <origin rpy="1.5707963 0 0" xyz="0 0 0"/>
    </visual>
    <collision>
      <origin rpy="1.5707963 0 0" xyz="0 0 0"/>
      <geometry>
        <cylinder length="0.05" radius="0.015"/>
      </geometry>
      <!-- <surface>
                    <friction>
                        <ode mu="${mu}" mu2="${mu2}"/>
                    </friction>
                </surface> -->
    </collision>
    <inertial>
      <mass value="1"/>
      <inertia ixx="0.1" ixy="0.0" ixz="0.0" iyy="0.1" iyz="0.0" izz="0.1"/>
    </inertial>
  </link>
  <joint name="right4_joint" type="continuous">
    <parent link="base_link"/>
    <child link="right4_link"/>
    <origin rpy="0 0 0" xyz="-0.075 0.095 -0.05"/>
    <axis xyz="0 1 0"/>
  </joint>
  <gazebo reference="right4_link">
    <material>Gazebo/Gray</material>
  </gazebo>
  <link name="right5_link">
    <visual>
      <geometry>
        <cylinder length="0.05" radius="0.015"/>
      </geometry>
      <origin rpy="1.5707963 0 0" xyz="0 0 0"/>
    </visual>
    <collision>
      <origin rpy="1.5707963 0 0" xyz="0 0 0"/>
      <geometry>
        <cylinder length="0.05" radius="0.015"/>
      </geometry>
      <!-- <surface>
                    <friction>
                        <ode mu="${mu}" mu2="${mu2}"/>
                    </friction>
                </surface> -->
    </collision>
    <inertial>
      <mass value="1"/>
      <inertia ixx="0.1" ixy="0.0" ixz="0.0" iyy="0.1" iyz="0.0" izz="0.1"/>
    </inertial>
  </link>
  <joint name="right5_joint" type="continuous">
    <parent link="base_link"/>
    <child link="right5_link"/>
    <origin rpy="0 0 0" xyz="-0.125 0.095 -0.05"/>
    <axis xyz="0 1 0"/>
  </joint>
  <gazebo reference="right5_link">
    <material>Gazebo/Gray</material>
  </gazebo>
  <link name="right_back_link">
    <visual>
      <geometry>
        <cylinder length="0.05" radius="0.0275"/>
      </geometry>
      <origin rpy="1.5707963 0 0" xyz="0 0 0"/>
    </visual>
    <collision>
      <origin rpy="1.5707963 0 0" xyz="0 0 0"/>
      <geometry>
        <cylinder length="0.05" radius="0.0275"/>
      </geometry>
      <!-- <surface>
                    <friction>
                        <ode mu="${mu}" mu2="${mu2}"/>
                    </friction>
                </surface> -->
    </collision>
    <inertial>
      <mass value="1"/>
      <inertia ixx="0.1" ixy="0.0" ixz="0.0" iyy="0.1" iyz="0.0" izz="0.1"/>
    </inertial>
  </link>
  <joint name="right_back_joint" type="continuous">
    <parent link="base_link"/>
    <child link="right_back_link"/>
    <origin rpy="0 0 0" xyz="-0.125 0.095 -0.005"/>
    <axis xyz="0 1 0"/>
  </joint>
  <gazebo reference="right_back_link">
    <material>Gazebo/Gray</material>
  </gazebo>
  <!-- <xacro:wheel_func wheel_name="rightv" xyz="-0.1 0.15 -0.04" rpy="0 0 0" radius="0.0275" length="0.05" mu="4" mu2="4"/> -->
  <gazebo reference="base_link">
    <material>Gazebo/Green</material>
  </gazebo>
  <gazebo reference="plat_link">
    <material>Gazebo/Black</material>
  </gazebo>
  <gazebo reference="laser_link">
    <material>Gazebo/Gray</material>
  </gazebo>
  <gazebo reference="tripod_link">
    <material>Gazebo/Gray</material>
  </gazebo>
  <gazebo reference="camera_link">
    <material>Gazebo/Gray</material>
  </gazebo>
  <!-- <link name="caster_link">
      <visual>
        <origin xyz="0 0 0" rpy="1.57079 0 0"/>
        <geometry>
            <sphere radius="0.015"/>
        </geometry>
          <material name="black">
            <color rgba="0.0 0.0 0.0 0.5" /> 
          </material>
      </visual>
      <collision>
        <origin xyz="0 0 0" rpy="1.57079 0 0"/>
        <geometry>
            <sphere radius="0.015"/>
        </geometry>
          <material name="black">
            <color rgba="0.0 0.0 0.0 0.5" /> 
          </material>
          <surface>
            <friction>
                <ode mu="0" mu2="0"/>
            </friction>
        </surface>
      </collision>
      <xacro:default_inertial mass="0.3"/>
  </link>
    
  <joint name="caster_joint" type="fixed">
      <parent link="base_link" />
      <child link="caster_link" />
      <origin xyz="0.15 0.0 -0.05" />
      <axis xyz="0 1 0" />
  </joint> -->
  <gazebo>
    <plugin filename="libgazebo_ros_planar_move.so" name="diff_drive">
      <leftFrontJoint>left0_joint</leftFrontJoint>
      <rightFrontJoint>right0_joint</rightFrontJoint>
      <leftRearJoint>left5_joint</leftRearJoint>
      <rightRearJoint>right5_joint</rightRearJoint>
      <commandTopic>cmd_vel</commandTopic>
      <odometryTopic>odom</odometryTopic>
      <odometryFrame>odom</odometryFrame>
      <robotNamespace>/</robotNamespace>
      <odometryRate>10.0</odometryRate>
      <publish_odom>true</publish_odom>
      <publish_odom_tf>true</publish_odom_tf>
      <publish_wheel_tf>true</publish_wheel_tf>
      <robotBaseFrame>base_footprint</robotBaseFrame>
    </plugin>
  </gazebo>
  <gazebo reference="laser_link">
    <sensor name="laser_sensor" type="ray">
      <always_on>true</always_on>
      <visualize>false</visualize>
      <update_rate>10</update_rate>
      <pose>0 0 0.075 0 0 0</pose>
      <ray>
        <scan>
          <horizontal>
            <samples>360</samples>
            <resolution>1.000000</resolution>
            <!-- <min_angle>-2.3561944901923449288469825374596</min_angle>
                <max_angle>2.3561944901923449288469825374596</max_angle> -->
            <min_angle>0.00</min_angle>
            <max_angle>6.28</max_angle>
          </horizontal>
        </scan>
        <range>
          <min>0.200000</min>
          <max>50</max>
          <resolution>0.005000</resolution>
        </range>
        <noise>
          <type>gaussian</type>
          <mean>0.0</mean>
          <stddev>0.001</stddev>
        </noise>
      </ray>
      <plugin filename="libgazebo_ros_ray_sensor.so" name="laserscan">
        <ros>
          <!-- <namespace>/tb3</namespace> -->
          <remapping>~/out:=scan</remapping>
        </ros>
        <output_type>sensor_msgs/LaserScan</output_type>
        <frame_name>laser_link</frame_name>
      </plugin>
    </sensor>
  </gazebo>
</robot>
